Workbook

Sheet Menu
A1: Item Name | B1: Category | C1: S | D1: M | E1: L | F1: -
A2: Baby Cheese Pizza | B2: Pizza | C2: 49
A3: Onion Cheese Pizza | B3: Pizza | C3: 59 | D3: 109 | E3: 199
A4: Tomato Cheese Pizza | B4: Pizza | C4: 59 | D4: 109 | E4: 199
A5: Capsicum Cheese Pizza | B5: Pizza | C5: 59 | D5: 109 | E5: 199
A6: Cheese N Corn Pizza | B6: Pizza | C6: 69 | D6: 109 | E6: 209
A7: Onion Tomato Pizza | B7: Pizza | C7: 79 | D7: 129 | E7: 209
A8: Onion Capsicum Pizza | B8: Pizza | C8: 79 | D8: 129 | E8: 209
A9: Sweet Corn Onion Pizza | B9: Pizza | C9: 79 | D9: 129 | E9: 209
A10: Mix Veg Margharita Pizza | B10: Pizza | C10: 99 | D10: 149 | E10: 249
A11: Paneer Pizza | B11: Pizza | C11: 109 | D11: 199 | E11: 289
A12: Spicy Mix Veg Pizza | B12: Pizza | C12: 109 | D12: 199 | E12: 299
A13: Tandoori Pizza | B13: Pizza | C13: 109 | D13: 199 | E13: 299
A14: Onion Paneer Pizza | B14: Pizza | C14: 109 | D14: 189 | E14: 289
... A20: Chicken Pizza | B20: Pizza | C20: 170 | D20: 279 | E20: 370
A21: Kulhad Pizza | B21: Pizza | F21: 99
A22: Veg Burger | B22: Burger | F22: 39
A23: Veg Cheese Burger | B23: Burger | F23: 59
A24: Mr.Pizza's Special Burger | B24: Burger | F24: 99
A25: Non Veg Burger | B25: Burger | F25: 69
A26: Veg Hot Dog | B26: Hot Dog | F26: 70
A27: Non-Veg Hot Dog | B27: Hot Dog | F27: 110
A28: Cheese Corn Garlic Bread | B28: Bread | F28: 49
A29: Stuffed Garlic Bread | B29: Bread | F29: 89
A30: Oreo Shake | B30: Shake | F30: 70
A31: Vanilla Shake | B31: Shake | F31: 50
A32: Chocolate Shake | B32: Shake | F32: 70
... A55: Extra Patty | B55: Add-on | F55: 20

Sheet Sales Data
A1: Mr. Pizza — Sales Data Entry
A2: Date (DD-MM-YYYY) | B2: Day (Auto) | C2: Category (Auto) | D2: Item Name | E2: Size | F2: Qty | G2: Unit Price (₹ Auto) | H2: Total Price (₹) | I2: Daily Total (₹ notebook) | J2: Notes
A3: 45170 | B3: =IF(A3="","",TEXT(A3,"dddd")) -> Friday | C3: =IF(D3="","",VLOOKUP(D3,Menu!$A$2:$B$105,2,0)) -> Pizza | D3: Kulhad Pizza | E3: - | F3: 1 | G3: {=IF(OR(D3="",E3=""),"",IFERROR(CHOOSE(MATCH(E3,{"S","M","L","-"},0),VLOOKUP(D3,Menu!$A$2:$F$105,3,0),VLOOKUP(D3,Menu!$A$2:$F$105,4,0),VLOOKUP(D3,Menu!$A$2:$F$105,5,0),VLOOKUP(D3,Menu!$A$2:$F$105,6,0)),"N/A"))} -> 99 | H3: =IF(OR(F3="",G3=""),"",F3*G3) -> 99 | I3: =IF(A3="","",SUMIF($A$3:$A$496,A3,$H$3:$H$1048)) -> 913
A4: 45170 | B4: =IF(A4="","",TEXT(A4,"dddd")) -> Friday | C4: =IF(D4="","",VLOOKUP(D4,Menu!$A$2:$B$105,2,0)) -> Pizza | D4: Cheese N Corn Pizza | E4: M | F4: 2 | G4: {=IF(OR(D4="",E4=""),"",IFERROR(CHOOSE(MATCH(E4,{"S","M","L","-"},0),VLOOKUP(D4,Menu!$A$2:$F$105,3,0),VLOOKUP(D4,Menu!$A$2:$F$105,4,0),VLOOKUP(D4,Menu!$A$2:$F$105,5,0),VLOOKUP(D4,Menu!$A$2:$F$105,6,0)),"N/A"))} -> 109 | H4: =IF(OR(F4="",G4=""),"",F4*G4) -> 218 | I4: =IF(A4="","",SUMIF($A$3:$A$496,A4,$H$3:$H$1048)) -> 913
A5: 45170 | B5: =IF(A5="","",TEXT(A5,"dddd")) -> Friday | C5: =IF(D5="","",VLOOKUP(D5,Menu!$A$2:$B$105,2,0)) -> Pizza | D5: Peppy Paneer Pizza | E5: S | F5: 1 | G5: {=IF(OR(D5="",E5=""),"",IFERROR(CHOOSE(MATCH(E5,{"S","M","L","-"},0),VLOOKUP(D5,Menu!$A$2:$F$105,3,0),VLOOKUP(D5,Menu!$A$2:$F$105,4,0),VLOOKUP(D5,Menu!$A$2:$F$105,5,0),VLOOKUP(D5,Menu!$A$2:$F$105,6,0)),"N/A"))} -> 119 | H5: =IF(OR(F5="",G5=""),"",F5*G5) -> 119 | I5: =IF(A5="","",SUMIF($A$3:$A$496,A5,$H$3:$H$1048)) -> 913
A6: 45170 | B6: =IF(A6="","",TEXT(A6,"dddd")) -> Friday | C6: =IF(D6="","",VLOOKUP(D6,Menu!$A$2:$B$105,2,0)) -> Dessert | D6: Strawberry Ice Cream | E6: - | F6: 1 | G6: {=IF(OR(D6="",E6=""),"",IFERROR(CHOOSE(MATCH(E6,{"S","M","L","-"},0),VLOOKUP(D6,Menu!$A$2:$F$105,3,0),VLOOKUP(D6,Menu!$A$2:$F$105,4,0),VLOOKUP(D6,Menu!$A$2:$F$105,5,0),VLOOKUP(D6,Menu!$A$2:$F$105,6,0)),"N/A"))} -> 30 | H6: =IF(OR(F6="",G6=""),"",F6*G6) -> 30 | I6: =IF(A6="","",SUMIF($A$3:$A$496,A6,$H$3:$H$1048)) -> 913
A7: 45170 | B7: =IF(A7="","",TEXT(A7,"dddd")) -> Friday | C7: =IF(D7="","",VLOOKUP(D7,Menu!$A$2:$B$105,2,0)) -> Pizza | D7: Cheese N Corn Pizza | E7: S | F7: 1 | G7: {=IF(OR(D7="",E7=""),"",IFERROR(CHOOSE(MATCH(E7,{"S","M","L","-"},0),VLOOKUP(D7,Menu!$A$2:$F$105,3,0),VLOOKUP(D7,Menu!$A$2:$F$105,4,0),VLOOKUP(D7,Menu!$A$2:$F$105,5,0),VLOOKUP(D7,Menu!$A$2:$F$105,6,0)),"N/A"))} -> 69 | H7: =IF(OR(F7="",G7=""),"",F7*G7) -> 69 | I7: =IF(A7="","",SUMIF($A$3:$A$496,A7,$H$3:$H$1048)) -> 913
A8: 45170 | B8: =IF(A8="","",TEXT(A8,"dddd")) -> Friday | C8: =IF(D8="","",VLOOKUP(D8,Menu!$A$2:$B$105,2,0)) -> Pizza | D8: Tandoori Pizza | E8: M | F8: 1 | G8: {=IF(OR(D8="",E8=""),"",IFERROR(CHOOSE(MATCH(E8,{"S","M","L","-"},0),VLOOKUP(D8,Menu!$A$2:$F$105,3,0),VLOOKUP(D8,Menu!$A$2:$F$105,4,0),VLOOKUP(D8,Menu!$A$2:$F$105,5,0),VLOOKUP(D8,Menu!$A$2:$F$105,6,0)),"N/A"))} -> 199 | H8: =IF(OR(F8="",G8=""),"",F8*G8) -> 199 | I8: =IF(A8="","",SUMIF($A$3:$A$496,A8,$H$3:$H$1048)) -> 913
A9: 45170 | B9: =IF(A9="","",TEXT(A9,"dddd")) -> Friday | C9: =IF(D9="","",VLOOKUP(D9,Menu!$A$2:$B$105,2,0)) -> Pizza | D9: Mix Veg Margharita Pizza | E9: S | F9: 1 | G9: {=IF(OR(D9="",E9=""),"",IFERROR(CHOOSE(MATCH(E9,{"S","M","L","-"},0),VLOOKUP(D9,Menu!$A$2:$F$105,3,0),VLOOKUP(D9,Menu!$A$2:$F$105,4,0),VLOOKUP(D9,Menu!$A$2:$F$105,5,0),VLOOKUP(D9,Menu!$A$2:$F$105,6,0)),"N/A"))} -> 99 | H9: =IF(OR(F9="",G9=""),"",F9*G9) -> 99 | I9: =IF(A9="","",SUMIF($A$3:$A$496,A9,$H$3:$H$1048)) -> 913
A10: 45170 | B10: =IF(A10="","",TEXT(A10,"dddd")) -> Friday | C10: =IF(D10="","",VLOOKUP(D10,Menu!$A$2:$B$105,2,0)) -> Beverage | D10: Cold Drink | E10: - | F10: 4 | G10: {=IF(OR(D10="",E10=""),"",IFERROR(CHOOSE(MATCH(E10,{"S","M","L","-"},0),VLOOKUP(D10,Menu!$A$2:$F$105,3,0),VLOOKUP(D10,Menu!$A$2:$F$105,4,0),VLOOKUP(D10,Menu!$A$2:$F$105,5,0),VLOOKUP(D10,Menu!$A$2:$F$105,6,0)),"N/A"))} -> 20 | H10: =IF(OR(F10="",G10=""),"",F10*G10) -> 80 | I10: =IF(A10="","",SUMIF($A$3:$A$496,A10,$H$3:$H$1048)) -> 913
A11: 45171 | B11: =IF(A11="","",TEXT(A11,"dddd")) -> Saturday | C11: =IF(D11="","",VLOOKUP(D11,Menu!$A$2:$B$105,2,0)) -> Beverage | D11: Cold Drink | E11: - | F11: 10 | G11: {=IF(OR(D11="",E11=""),"",IFERROR(CHOOSE(MATCH(E11,{"S","M","L","-"},0),VLOOKUP(D11,Menu!$A$2:$F$105,3,0),VLOOKUP(D11,Menu!$A$2:$F$105,4,0),VLOOKUP(D11,Menu!$A$2:$F$105,5,0),VLOOKUP(D11,Menu!$A$2:$F$105,6,0)),"N/A"))} -> 20 | H11: =IF(OR(F11="",G11=""),"",F11*G11) -> 200 | I11: =IF(A11="","",SUMIF($A$3:$A$496,A11,$H$3:$H$1048)) -> 1678
A12: 45171 | B12: =IF(A12="","",TEXT(A12,"dddd")) -> Saturday | C12: =IF(D12="","",VLOOKUP(D12,Menu!$A$2:$B$105,2,0)) -> Shake | D12: Butterscotch Shake | E12: - | F12: 1 | G12: {=IF(OR(D12="",E12=""),"",IFERROR(CHOOSE(MATCH(E12,{"S","M","L","-"},0),VLOOKUP(D12,Menu!$A$2:$F$105,3,0),VLOOKUP(D12,Menu!$A$2:$F$105,4,0),VLOOKUP(D12,Menu!$A$2:$F$105,5,0),VLOOKUP(D12,Menu!$A$2:$F$105,6,0)),"N/A"))} -> 60 | H12: =IF(OR(F12="",G12=""),"",F12*G12) -> 60 | I12: =IF(A12="","",SUMIF($A$3:$A$496,A12,$H$3:$H$1048)) -> 1678
A13: 45171 | B13: =IF(A13="","",TEXT(A13,"dddd")) -> Saturday | C13: =IF(D13="","",VLOOKUP(D13,Menu!$A$2:$B$105,2,0)) -> Shake | D13: Strawberry Shake | E13: - | F13: 1 | G13: {=IF(OR(D13="",E13=""),"",IFERROR(CHOOSE(MATCH(E13,{"S","M","L","-"},0),VLOOKUP(D13,Menu!$A$2:$F$105,3,0),VLOOKUP(D13,Menu!$A$2:$F$105,4,0),VLOOKUP(D13,Menu!$A$2:$F$105,5,0),VLOOKUP(D13,Menu!$A$2:$F$105,6,0)),"N/A"))} -> 50 | H13: =IF(OR(F13="",G13=""),"",F13*G13) -> 50 | I13: =IF(A13="","",SUMIF($A$3:$A$496,A13,$H$3:$H$1048)) -> 1678
A14: 45171 | B14: =IF(A14="","",TEXT(A14,"dddd")) -> Saturday | C14: =IF(D14="","",VLOOKUP(D14,Menu!$A$2:$B$105,2,0)) -> Pizza | D14: Kulhad Pizza | E14: - | F14: 1 | G14: {=IF(OR(D14="",E14=""),"",IFERROR(CHOOSE(MATCH(E14,{"S","M","L","-"},0),VLOOKUP(D14,Menu!$A$2:$F$105,3,0),VLOOKUP(D14,Menu!$A$2:$F$105,4,0),VLOOKUP(D14,Menu!$A$2:$F$105,5,0),VLOOKUP(D14,Menu!$A$2:$F$105,6,0)),"N/A"))} -> 99 | H14: =IF(OR(F14="",G14=""),"",F14*G14) -> 99 | I14: =IF(A14="","",SUMIF($A$3:$A$496,A14,$H$3:$H$1048)) -> 1678
... A493: 45235 | B493: =IF(A493="","",TEXT(A493,"dddd")) -> Sunday | C493: =IF(D493="","",VLOOKUP(D493,Menu!$A$2:$B$105,2,0)) -> Pizza | D493: Baby Cheese Pizza | E493: S | F493: 1 | G493: {=IF(OR(D493="",E493=""),"",IFERROR(CHOOSE(MATCH(E493,{"S","M","L","-"},0),VLOOKUP(D493,Menu!$A$2:$F$105,3,0),VLOOKUP(D493,Menu!$A$2:$F$105,4,0),VLOOKUP(D493,Menu!$A$2:$F$105,5,0),VLOOKUP(D493,Menu!$A$2:$F$105,6,0)),"N/A"))} -> 49 | H493: =IF(OR(F493="",G493=""),"",F493*G493) -> 49 | I493: =IF(A493="","",SUMIF($A$3:$A$496,A493,$H$3:$H$1048)) -> 1658
A494: 45236 | B494: =IF(A494="","",TEXT(A494,"dddd")) -> Monday | C494: =IF(D494="","",VLOOKUP(D494,Menu!$A$2:$B$105,2,0)) -> Pizza | D494: Mix Veg Margharita Pizza | E494: L | F494: 1 | G494: {=IF(OR(D494="",E494=""),"",IFERROR(CHOOSE(MATCH(E494,{"S","M","L","-"},0),VLOOKUP(D494,Menu!$A$2:$F$105,3,0),VLOOKUP(D494,Menu!$A$2:$F$105,4,0),VLOOKUP(D494,Menu!$A$2:$F$105,5,0),VLOOKUP(D494,Menu!$A$2:$F$105,6,0)),"N/A"))} -> 249 | H494: =IF(OR(F494="",G494=""),"",F494*G494) -> 249 | I494: =IF(A494="","",SUMIF($A$3:$A$2048,A494,$H$3:$H$2048)) -> 840
A495: 45236 | B495: =IF(A495="","",TEXT(A495,"dddd")) -> Monday | C495: =IF(D495="","",VLOOKUP(D495,Menu!$A$2:$B$105,2,0)) -> Pizza | D495: Spicy Mix Veg Pizza | E495: M | F495: 1 | G495: {=IF(OR(D495="",E495=""),"",IFERROR(CHOOSE(MATCH(E495,{"S","M","L","-"},0),VLOOKUP(D495,Menu!$A$2:$F$105,3,0),VLOOKUP(D495,Menu!$A$2:$F$105,4,0),VLOOKUP(D495,Menu!$A$2:$F$105,5,0),VLOOKUP(D495,Menu!$A$2:$F$105,6,0)),"N/A"))} -> 199 | H495: =IF(OR(F495="",G495=""),"",F495*G495) -> 199 | I495: =IF(A495="","",SUMIF($A$3:$A$2048,A495,$H$3:$H$2048)) -> 840
A496: 45236 | B496: =IF(A496="","",TEXT(A496,"dddd")) -> Monday | C496: =IF(D496="","",VLOOKUP(D496,Menu!$A$2:$B$105,2,0)) -> Pizza | D496: Onion Tomato Pizza | E496: S | F496: 1 | G496: {=IF(OR(D496="",E496=""),"",IFERROR(CHOOSE(MATCH(E496,{"S","M","L","-"},0),VLOOKUP(D496,Menu!$A$2:$F$105,3,0),VLOOKUP(D496,Menu!$A$2:$F$105,4,0),VLOOKUP(D496,Menu!$A$2:$F$105,5,0),VLOOKUP(D496,Menu!$A$2:$F$105,6,0)),"N/A"))} -> 79 | H496: =IF(OR(F496="",G496=""),"",F496*G496) -> 79 | I496: =IF(A496="","",SUMIF($A$3:$A$2048,A496,$H$3:$H$2048)) -> 840
A497: 45236 | B497: =IF(A497="","",TEXT(A497,"dddd")) -> Monday | C497: =IF(D497="","",VLOOKUP(D497,Menu!$A$2:$B$105,2,0)) -> Burger | D497: Veg Burger | E497: - | F497: 6 | G497: {=IF(OR(D497="",E497=""),"",IFERROR(CHOOSE(MATCH(E497,{"S","M","L","-"},0),VLOOKUP(D497,Menu!$A$2:$F$105,3,0),VLOOKUP(D497,Menu!$A$2:$F$105,4,0),VLOOKUP(D497,Menu!$A$2:$F$105,5,0),VLOOKUP(D497,Menu!$A$2:$F$105,6,0)),"N/A"))} -> 39 | H497: =IF(OR(F497="",G497=""),"",F497*G497) -> 234 | I497: =IF(A497="","",SUMIF($A$3:$A$2048,A497,$H$3:$H$2048)) -> 840
A498: 45236 | B498: =IF(A498="","",TEXT(A498,"dddd")) -> Monday | C498: =IF(D498="","",VLOOKUP(D498,Menu!$A$2:$B$105,2,0)) -> Pizza | D498: Onion Cheese Pizza | E498: S | F498: 1 | G498: {=IF(OR(D498="",E498=""),"",IFERROR(CHOOSE(MATCH(E498,{"S","M","L","-"},0),VLOOKUP(D498,Menu!$A$2:$F$105,3,0),VLOOKUP(D498,Menu!$A$2:$F$105,4,0),VLOOKUP(D498,Menu!$A$2:$F$105,5,0),VLOOKUP(D498,Menu!$A$2:$F$105,6,0)),"N/A"))} -> 59 | H498: =IF(OR(F498="",G498=""),"",F498*G498) -> 59 | I498: =IF(A498="","",SUMIF($A$3:$A$2048,A498,$H$3:$H$2048)) -> 840
A499: 45236 | B499: =IF(A499="","",TEXT(A499,"dddd")) -> Monday | C499: =IF(D499="","",VLOOKUP(D499,Menu!$A$2:$B$105,2,0)) -> Beverage | D499: Cold Drink | E499: - | F499: 1 | G499: {=IF(OR(D499="",E499=""),"",IFERROR(CHOOSE(MATCH(E499,{"S","M","L","-"},0),VLOOKUP(D499,Menu!$A$2:$F$105,3,0),VLOOKUP(D499,Menu!$A$2:$F$105,4,0),VLOOKUP(D499,Menu!$A$2:$F$105,5,0),VLOOKUP(D499,Menu!$A$2:$F$105,6,0)),"N/A"))} -> 20 | H499: =IF(OR(F499="",G499=""),"",F499*G499) -> 20 | I499: =IF(A499="","",SUMIF($A$3:$A$2048,A499,$H$3:$H$2048)) -> 840
A500: 45237 | B500: =IF(A500="","",TEXT(A500,"dddd")) -> Tuesday | C500: =IF(D500="","",VLOOKUP(D500,Menu!$A$2:$B$105,2,0)) -> Burger | D500: Veg Burger | E500: - | F500: 2 | G500: {=IF(OR(D500="",E500=""),"",IFERROR(CHOOSE(MATCH(E500,{"S","M","L","-"},0),VLOOKUP(D500,Menu!$A$2:$F$105,3,0),VLOOKUP(D500,Menu!$A$2:$F$105,4,0),VLOOKUP(D500,Menu!$A$2:$F$105,5,0),VLOOKUP(D500,Menu!$A$2:$F$105,6,0)),"N/A"))} -> 39 | H500: =IF(OR(F500="",G500=""),"",F500*G500) -> 78 | I500: =IF(A500="","",SUMIF($A$3:$A$2048,A500,$H$3:$H$2048)) -> 206
A501: 45237 | B501: =IF(A501="","",TEXT(A501,"dddd")) -> Tuesday | C501: =IF(D501="","",VLOOKUP(D501,Menu!$A$2:$B$105,2,0)) -> Pizza | D501: Cheese N Corn Pizza | E501: S | F501: 1 | G501: {=IF(OR(D501="",E501=""),"",IFERROR(CHOOSE(MATCH(E501,{"S","M","L","-"},0),VLOOKUP(D501,Menu!$A$2:$F$105,3,0),VLOOKUP(D501,Menu!$A$2:$F$105,4,0),VLOOKUP(D501,Menu!$A$2:$F$105,5,0),VLOOKUP(D501,Menu!$A$2:$F$105,6,0)),"N/A"))} -> 69 | H501: =IF(OR(F501="",G501=""),"",F501*G501) -> 69 | I501: =IF(A501="","",SUMIF($A$3:$A$2048,A501,$H$3:$H$2048)) -> 206
A502: 45237 | B502: =IF(A502="","",TEXT(A502,"dddd")) -> Tuesday | C502: =IF(D502="","",VLOOKUP(D502,Menu!$A$2:$B$105,2,0)) -> Pizza | D502: Onion Cheese Pizza | E502: S | F502: 1 | G502: {=IF(OR(D502="",E502=""),"",IFERROR(CHOOSE(MATCH(E502,{"S","M","L","-"},0),VLOOKUP(D502,Menu!$A$2:$F$105,3,0),VLOOKUP(D502,Menu!$A$2:$F$105,4,0),VLOOKUP(D502,Menu!$A$2:$F$105,5,0),VLOOKUP(D502,Menu!$A$2:$F$105,6,0)),"N/A"))} -> 59 | H502: =IF(OR(F502="",G502=""),"",F502*G502) -> 59 | I502: =IF(A502="","",SUMIF($A$3:$A$2048,A502,$H$3:$H$2048)) -> 206
A503: 45238 | B503: =IF(A503="","",TEXT(A503,"dddd")) -> Wednesday | C503: =IF(D503="","",VLOOKUP(D503,Menu!$A$2:$B$105,2,0)) -> Pizza | D503: Baby Cheese Pizza | E503: S | F503: 3 | G503: {=IF(OR(D503="",E503=""),"",IFERROR(CHOOSE(MATCH(E503,{"S","M","L","-"},0),VLOOKUP(D503,Menu!$A$2:$F$105,3,0),VLOOKUP(D503,Menu!$A$2:$F$105,4,0),VLOOKUP(D503,Menu!$A$2:$F$105,5,0),VLOOKUP(D503,Menu!$A$2:$F$105,6,0)),"N/A"))} -> 49 | H503: =IF(OR(F503="",G503=""),"",F503*G503) -> 147 | I503: =IF(A503="","",SUMIF($A$3:$A$2048,A503,$H$3:$H$2048)) -> 591
A504: 45238 | B504: =IF(A504="","",TEXT(A504,"dddd")) -> Wednesday | C504: =IF(D504="","",VLOOKUP(D504,Menu!$A$2:$B$105,2,0)) -> Burger | D504: Veg Burger | E504: - | F504: 2 | G504: {=IF(OR(D504="",E504=""),"",IFERROR(CHOOSE(MATCH(E504,{"S","M","L","-"},0),VLOOKUP(D504,Menu!$A$2:$F$105,3,0),VLOOKUP(D504,Menu!$A$2:$F$105,4,0),VLOOKUP(D504,Menu!$A$2:$F$105,5,0),VLOOKUP(D504,Menu!$A$2:$F$105,6,0)),"N/A"))} -> 39 | H504: =IF(OR(F504="",G504=""),"",F504*G504) -> 78 | I504: =IF(A504="","",SUMIF($A$3:$A$2048,A504,$H$3:$H$2048)) -> 591
A505: 45238 | B505: =IF(A505="","",TEXT(A505,"dddd")) -> Wednesday | C505: =IF(D505="","",VLOOKUP(D505,Menu!$A$2:$B$105,2,0)) -> Pizza | D505: Cheese N Corn Pizza | E505: S | F505: 1 | G505: {=IF(OR(D505="",E505=""),"",IFERROR(CHOOSE(MATCH(E505,{"S","M","L","-"},0),VLOOKUP(D505,Menu!$A$2:$F$105,3,0),VLOOKUP(D505,Menu!$A$2:$F$105,4,0),VLOOKUP(D505,Menu!$A$2:$F$105,5,0),VLOOKUP(D505,Menu!$A$2:$F$105,6,0)),"N/A"))} -> 69 | H505: =IF(OR(F505="",G505=""),"",F505*G505) -> 69 | I505: =IF(A505="","",SUMIF($A$3:$A$2048,A505,$H$3:$H$2048)) -> 591
... A913: 45304 | B913: =IF(A913="","",TEXT(A913,"dddd")) -> Saturday | C913: =IF(D913="","",VLOOKUP(D913,Menu!$A$2:$B$105,2,0)) -> Pizza | D913: Capsicum Cheese Pizza | E913: S | F913: 1 | G913: {=IF(OR(D913="",E913=""),"",IFERROR(CHOOSE(MATCH(E913,{"S","M","L","-"},0),VLOOKUP(D913,Menu!$A$2:$F$105,3,0),VLOOKUP(D913,Menu!$A$2:$F$105,4,0),VLOOKUP(D913,Menu!$A$2:$F$105,5,0),VLOOKUP(D913,Menu!$A$2:$F$105,6,0)),"N/A"))} -> 59 | H913: =IF(OR(F913="",G913=""),"",F913*G913) -> 59 | I913: =IF(A913="","",SUMIF($A$3:$A$2048,A913,$H$3:$H$2048)) -> 2781
A914: 45305 | B914: =IF(A914="","",TEXT(A914,"dddd")) -> Sunday | C914: =IF(D914="","",VLOOKUP(D914,Menu!$A$2:$B$105,2,0)) -> Pizza | D914: Kulhad Pizza | E914: - | F914: 75 | G914: {=IF(OR(D914="",E914=""),"",IFERROR(CHOOSE(MATCH(E914,{"S","M","L","-"},0),VLOOKUP(D914,Menu!$A$2:$F$105,3,0),VLOOKUP(D914,Menu!$A$2:$F$105,4,0),VLOOKUP(D914,Menu!$A$2:$F$105,5,0),VLOOKUP(D914,Menu!$A$2:$F$105,6,0)),"N/A"))} -> 99 | H914: =IF(OR(F914="",G914=""),"",F914*G914) -> 7425 | I914: =IF(A914="","",SUMIF($A$3:$A$2048,A914,$H$3:$H$2048)) -> 7425 | J914: Catering event
A915: 45306 | B915: =IF(A915="","",TEXT(A915,"dddd")) -> Monday | C915: =IF(D915="","",VLOOKUP(D915,Menu!$A$2:$B$105,2,0)) -> Pizza | D915: Cheese N Corn Pizza | E915: S | F915: 1 | G915: {=IF(OR(D915="",E915=""),"",IFERROR(CHOOSE(MATCH(E915,{"S","M","L","-"},0),VLOOKUP(D915,Menu!$A$2:$F$105,3,0),VLOOKUP(D915,Menu!$A$2:$F$105,4,0),VLOOKUP(D915,Menu!$A$2:$F$105,5,0),VLOOKUP(D915,Menu!$A$2:$F$105,6,0)),"N/A"))} -> 69 | H915: =IF(OR(F915="",G915=""),"",F915*G915) -> 69 | I915: =IF(A915="","",SUMIF($A$3:$A$2048,A915,$H$3:$H$2048)) -> 386
A916: 45306 | B916: =IF(A916="","",TEXT(A916,"dddd")) -> Monday | C916: =IF(D916="","",VLOOKUP(D916,Menu!$A$2:$B$105,2,0)) -> Pizza | D916: Mix Veg Margharita Pizza | E916: M | F916: 1 | G916: {=IF(OR(D916="",E916=""),"",IFERROR(CHOOSE(MATCH(E916,{"S","M","L","-"},0),VLOOKUP(D916,Menu!$A$2:$F$105,3,0),VLOOKUP(D916,Menu!$A$2:$F$105,4,0),VLOOKUP(D916,Menu!$A$2:$F$105,5,0),VLOOKUP(D916,Menu!$A$2:$F$105,6,0)),"N/A"))} -> 149 | H916: =IF(OR(F916="",G916=""),"",F916*G916) -> 149 | I916: =IF(A916="","",SUMIF($A$3:$A$2048,A916,$H$3:$H$2048)) -> 386
A917: 45306 | B917: =IF(A917="","",TEXT(A917,"dddd")) -> Monday | C917: =IF(D917="","",VLOOKUP(D917,Menu!$A$2:$B$105,2,0)) -> Pizza | D917: Onion Cheese Pizza | E917: S | F917: 1 | G917: {=IF(OR(D917="",E917=""),"",IFERROR(CHOOSE(MATCH(E917,{"S","M","L","-"},0),VLOOKUP(D917,Menu!$A$2:$F$105,3,0),VLOOKUP(D917,Menu!$A$2:$F$105,4,0),VLOOKUP(D917,Menu!$A$2:$F$105,5,0),VLOOKUP(D917,Menu!$A$2:$F$105,6,0)),"N/A"))} -> 59 | H917: =IF(OR(F917="",G917=""),"",F917*G917) -> 59 | I917: =IF(A917="","",SUMIF($A$3:$A$2048,A917,$H$3:$H$2048)) -> 386
A918: 45306 | B918: =IF(A918="","",TEXT(A918,"dddd")) -> Monday | C918: =IF(D918="","",VLOOKUP(D918,Menu!$A$2:$B$105,2,0)) -> Pizza | D918: Cheese N Corn Pizza | E918: M | F918: 1 | G918: {=IF(OR(D918="",E918=""),"",IFERROR(CHOOSE(MATCH(E918,{"S","M","L","-"},0),VLOOKUP(D918,Menu!$A$2:$F$105,3,0),VLOOKUP(D918,Menu!$A$2:$F$105,4,0),VLOOKUP(D918,Menu!$A$2:$F$105,5,0),VLOOKUP(D918,Menu!$A$2:$F$105,6,0)),"N/A"))} -> 109 | H918: =IF(OR(F918="",G918=""),"",F918*G918) -> 109 | I918: =IF(A918="","",SUMIF($A$3:$A$2048,A918,$H$3:$H$2048)) -> 386
A919: 45308 | B919: =IF(A919="","",TEXT(A919,"dddd")) -> Wednesday | C919: =IF(D919="","",VLOOKUP(D919,Menu!$A$2:$B$105,2,0)) -> Pizza | D919: Onion Paneer Pizza | E919: L | F919: 2 | G919: {=IF(OR(D919="",E919=""),"",IFERROR(CHOOSE(MATCH(E919,{"S","M","L","-"},0),VLOOKUP(D919,Menu!$A$2:$F$105,3,0),VLOOKUP(D919,Menu!$A$2:$F$105,4,0),VLOOKUP(D919,Menu!$A$2:$F$105,5,0),VLOOKUP(D919,Menu!$A$2:$F$105,6,0)),"N/A"))} -> 289 | H919: =IF(OR(F919="",G919=""),"",F919*G919) -> 578 | I919: =IF(A919="","",SUMIF($A$3:$A$2048,A919,$H$3:$H$2048)) -> 767
A920: 45308 | B920: =IF(A920="","",TEXT(A920,"dddd")) -> Wednesday | C920: =IF(D920="","",VLOOKUP(D920,Menu!$A$2:$B$105,2,0)) -> Pizza | D920: Onion Paneer Pizza | E920: M | F920: 1 | G920: {=IF(OR(D920="",E920=""),"",IFERROR(CHOOSE(MATCH(E920,{"S","M","L","-"},0),VLOOKUP(D920,Menu!$A$2:$F$105,3,0),VLOOKUP(D920,Menu!$A$2:$F$105,4,0),VLOOKUP(D920,Menu!$A$2:$F$105,5,0),VLOOKUP(D920,Menu!$A$2:$F$105,6,0)),"N/A"))} -> 189 | H920: =IF(OR(F920="",G920=""),"",F920*G920) -> 189 | I920: =IF(A920="","",SUMIF($A$3:$A$2048,A920,$H$3:$H$2048)) -> 767
A921: 45309 | B921: =IF(A921="","",TEXT(A921,"dddd")) -> Thursday | C921: =IF(D921="","",VLOOKUP(D921,Menu!$A$2:$B$105,2,0)) -> Pizza | D921: Baby Cheese Pizza | E921: S | F921: 1 | G921: {=IF(OR(D921="",E921=""),"",IFERROR(CHOOSE(MATCH(E921,{"S","M","L","-"},0),VLOOKUP(D921,Menu!$A$2:$F$105,3,0),VLOOKUP(D921,Menu!$A$2:$F$105,4,0),VLOOKUP(D921,Menu!$A$2:$F$105,5,0),VLOOKUP(D921,Menu!$A$2:$F$105,6,0)),"N/A"))} -> 49 | H921: =IF(OR(F921="",G921=""),"",F921*G921) -> 49 | I921: =IF(A921="","",SUMIF($A$3:$A$2048,A921,$H$3:$H$2048)) -> 366
A922: 45309 | B922: =IF(A922="","",TEXT(A922,"dddd")) -> Thursday | C922: =IF(D922="","",VLOOKUP(D922,Menu!$A$2:$B$105,2,0)) -> Pizza | D922: Capsicum Cheese Pizza | E922: S | F922: 1 | G922: {=IF(OR(D922="",E922=""),"",IFERROR(CHOOSE(MATCH(E922,{"S","M","L","-"},0),VLOOKUP(D922,Menu!$A$2:$F$105,3,0),VLOOKUP(D922,Menu!$A$2:$F$105,4,0),VLOOKUP(D922,Menu!$A$2:$F$105,5,0),VLOOKUP(D922,Menu!$A$2:$F$105,6,0)),"N/A"))} -> 59 | H922: =IF(OR(F922="",G922=""),"",F922*G922) -> 59 | I922: =IF(A922="","",SUMIF($A$3:$A$2048,A922,$H$3:$H$2048)) -> 366
A923: 45309 | B923: =IF(A923="","",TEXT(A923,"dddd")) -> Thursday | C923: =IF(D923="","",VLOOKUP(D923,Menu!$A$2:$B$105,2,0)) -> Pizza | D923: Sweet Corn Onion Pizza | E923: M | F923: 2 | G923: {=IF(OR(D923="",E923=""),"",IFERROR(CHOOSE(MATCH(E923,{"S","M","L","-"},0),VLOOKUP(D923,Menu!$A$2:$F$105,3,0),VLOOKUP(D923,Menu!$A$2:$F$105,4,0),VLOOKUP(D923,Menu!$A$2:$F$105,5,0),VLOOKUP(D923,Menu!$A$2:$F$105,6,0)),"N/A"))} -> 129 | H923: =IF(OR(F923="",G923=""),"",F923*G923) -> 258 | I923: =IF(A923="","",SUMIF($A$3:$A$2048,A923,$H$3:$H$2048)) -> 366
A924: 45310 | B924: =IF(A924="","",TEXT(A924,"dddd")) -> Friday | C924: =IF(D924="","",VLOOKUP(D924,Menu!$A$2:$B$105,2,0)) -> Pizza | D924: Baby Cheese Pizza | E924: S | F924: 2 | G924: {=IF(OR(D924="",E924=""),"",IFERROR(CHOOSE(MATCH(E924,{"S","M","L","-"},0),VLOOKUP(D924,Menu!$A$2:$F$105,3,0),VLOOKUP(D924,Menu!$A$2:$F$105,4,0),VLOOKUP(D924,Menu!$A$2:$F$105,5,0),VLOOKUP(D924,Menu!$A$2:$F$105,6,0)),"N/A"))} -> 49 | H924: =IF(OR(F924="",G924=""),"",F924*G924) -> 98 | I924: =IF(A924="","",SUMIF($A$3:$A$2048,A924,$H$3:$H$2048)) -> 207
A925: 45310 | B925: =IF(A925="","",TEXT(A925,"dddd")) -> Friday | C925: =IF(D925="","",VLOOKUP(D925,Menu!$A$2:$B$105,2,0)) -> Pizza | D925: Paneer Pizza | E925: S | F925: 1 | G925: {=IF(OR(D925="",E925=""),"",IFERROR(CHOOSE(MATCH(E925,{"S","M","L","-"},0),VLOOKUP(D925,Menu!$A$2:$F$105,3,0),VLOOKUP(D925,Menu!$A$2:$F$105,4,0),VLOOKUP(D925,Menu!$A$2:$F$105,5,0),VLOOKUP(D925,Menu!$A$2:$F$105,6,0)),"N/A"))} -> 109 | H925: =IF(OR(F925="",G925=""),"",F925*G925) -> 109 | I925: =IF(A925="","",SUMIF($A$3:$A$2048,A925,$H$3:$H$2048)) -> 207
...

Sheet Purchase Data
A1: Mr. Pizza — Purchase / Ingredient Bills
A2: Date | B2: Ingredient | C2: Quantity | D2: Unit (kg/ltr) | E2: Unit Price (₹) | F2: Total Cost (₹) | G2: Notes
F3: =IF(OR(C3="",E3=""),"",C3*E3)
F4: =IF(OR(C4="",E4=""),"",C4*E4)
F5: =IF(OR(C5="",E5=""),"",C5*E5)
F6: =IF(OR(C6="",E6=""),"",C6*E6)
F7: =IF(OR(C7="",E7=""),"",C7*E7)
F8: =IF(OR(C8="",E8=""),"",C8*E8)
F9: =IF(OR(C9="",E9=""),"",C9*E9)
F10: =IF(OR(C10="",E10=""),"",C10*E10)
F11: =IF(OR(C11="",E11=""),"",C11*E11)
F12: =IF(OR(C12="",E12=""),"",C12*E12)
F13: =IF(OR(C13="",E13=""),"",C13*E13)
F14: =IF(OR(C14="",E14=""),"",C14*E14)
... F148: =IF(OR(C148="",E148=""),"",C148*E148)

Sheet Summary analysis
A1: TABLE 1: Monthly Revenue Summary
A2: Month | B2: Revenue (₹) | C2: Units Sold | D2: Trading Days | E2: Transactions | F2: MoM Change (%) | G2: % of Total Revenue
A3: Sep 2023 | B3: =SUMPRODUCT((MONTH('Sales Data'!$A$3:$A$999)=9)*(YEAR('Sales Data'!$A$3:$A$999)=2023)*IFERROR('Sales Data'!$H$3:$H$999*1,0)) -> 34231 | C3: =SUMPRODUCT((MONTH('Sales Data'!$A$3:$A$999)=9)*(YEAR('Sales Data'!$A$3:$A$999)=2023)*IFERROR('Sales Data'!$F$3:$F$999*1,0)) -> 482 | D3: 29 | E3: =SUMPRODUCT(('Sales Data'!$H$3:$H$1044<>"")*(YEAR('Sales Data'!$A$3:$A$1044)=2023)*(MONTH('Sales Data'!$A$3:$A$1044)=9)*1) -> 248 | G3: =B3/SUM(B3:B7) -> 0.22376566
A4: Oct 2023 | B4: =SUMPRODUCT((MONTH('Sales Data'!$A$3:$A$999)=10)*(YEAR('Sales Data'!$A$3:$A$999)=2023)*IFERROR('Sales Data'!$H$3:$H$999*1,0)) -> 30661 | C4: =SUMPRODUCT((MONTH('Sales Data'!$A$3:$A$999)=10)*(YEAR('Sales Data'!$A$3:$A$999)=2023)*IFERROR('Sales Data'!$F$3:$F$999*1,0)) -> 395 | D4: 26 | E4: =SUMPRODUCT(('Sales Data'!$H$3:$H$1044<>"")*(YEAR('Sales Data'!$A$3:$A$1044)=2023)*(MONTH('Sales Data'!$A$3:$A$1044)=10)*1) -> 210 | F4: =IFERROR((B4-B3)/B3*100,"") -> -10.429143 | G4: =B4/SUM(B3:B7) -> 0.20042882
A5: Nov 2023 | B5: =SUMPRODUCT((MONTH('Sales Data'!$A$3:$A$999)=11)*(YEAR('Sales Data'!$A$3:$A$999)=2023)*IFERROR('Sales Data'!$H$3:$H$999*1,0)) -> 28332 | C5: =SUMPRODUCT((MONTH('Sales Data'!$A$3:$A$999)=11)*(YEAR('Sales Data'!$A$3:$A$999)=2023)*IFERROR('Sales Data'!$F$3:$F$999*1,0)) -> 299 | D5: 27 | E5: =SUMPRODUCT(('Sales Data'!$H$3:$H$1044<>"")*(YEAR('Sales Data'!$A$3:$A$1044)=2023)*(MONTH('Sales Data'!$A$3:$A$1044)=11)*1) -> 188 | F5: =IFERROR((B5-B4)/B4*100,"") -> -7.5959688 | G5: =B5/SUM(B3:B7) -> 0.18520431
A6: Dec 2023 | B6: =SUMPRODUCT((MONTH('Sales Data'!$A$3:$A$999)=12)*(YEAR('Sales Data'!$A$3:$A$999)=2023)*IFERROR('Sales Data'!$H$3:$H$999*1,0)) -> 25310 | C6: =SUMPRODUCT((MONTH('Sales Data'!$A$3:$A$999)=12)*(YEAR('Sales Data'!$A$3:$A$999)=2023)*IFERROR('Sales Data'!$F$3:$F$999*1,0)) -> 281 | D6: 30 | E6: =SUMPRODUCT(('Sales Data'!$H$3:$H$1044<>"")*(YEAR('Sales Data'!$A$3:$A$1044)=2023)*(MONTH('Sales Data'!$A$3:$A$1044)=12)*1) -> 179 | F6: =IFERROR((B6-B5)/B5*100,"") -> -10.666384 | G6: =B6/SUM(B3:B7) -> 0.16544971
A7: Jan 2024 | B7: =SUMPRODUCT((MONTH('Sales Data'!$A$3:$A$999)=1)*(YEAR('Sales Data'!$A$3:$A$999)=2024)*IFERROR('Sales Data'!$H$3:$H$999*1,0)) -> 34443 | C7: =SUMPRODUCT((MONTH('Sales Data'!$A$3:$A$999)=1)*(YEAR('Sales Data'!$A$3:$A$999)=2024)*IFERROR('Sales Data'!$F$3:$F$999*1,0)) -> 317 | D7: 27 | E7: =SUMPRODUCT(('Sales Data'!$H$3:$H$1044<>"")*(YEAR('Sales Data'!$A$3:$A$1044)=2024)*(MONTH('Sales Data'!$A$3:$A$1044)=1)*1) -> 172 | F7: =IFERROR((B7-B6)/B6*100,"") -> 36.084552 | G7: =B7/SUM(B3:B7) -> 0.22515149
A8: TOTAL | B8: =SUM(B3:B7) -> 152977 | C8: =SUM(C3:C7) -> 1774 | D8: =SUM(D3:D7) -> 139 | E8: =SUM(E3:E7) -> 997 | G8: =SUM(G3:G7) -> 1
A10: TABLE 2: Revenue by Product Category
A11: Category | B11: Revenue (₹) | C11: Qty Sold | D11: Transactions | E11: % of Total
A12: Pizza | B12: =SUMIF('Sales Data'!$C$3:$C$1044,A12,'Sales Data'!$H$3:$H$1044) -> 121956 | C12: =SUMIF('Sales Data'!$C$3:$C$1044,A12,'Sales Data'!$F$3:$F$1044) -> 1061 | D12: =COUNTIF('Sales Data'!$C$3:$C$1044,A12) -> 673 | E12: =IFERROR(B12/B$21*100,0) -> 79.721788
A13: Burger | B13: =SUMIF('Sales Data'!$C$3:$C$1044,A13,'Sales Data'!$H$3:$H$1044) -> 11933 | C13: =SUMIF('Sales Data'!$C$3:$C$1044,A13,'Sales Data'!$F$3:$F$1044) -> 299 | D13: =COUNTIF('Sales Data'!$C$3:$C$1044,A13) -> 121 | E13: =IFERROR(B13/B$21*100,0) -> 7.800519
A14: Shake | B14: =SUMIF('Sales Data'!$C$3:$C$1044,A14,'Sales Data'!$H$3:$H$1044) -> 7880 | C14: =SUMIF('Sales Data'!$C$3:$C$1044,A14,'Sales Data'!$F$3:$F$1044) -> 138 | D14: =COUNTIF('Sales Data'!$C$3:$C$1044,A14) -> 72 | E14: =IFERROR(B14/B$21*100,0) -> 5.1511011
A15: Dessert | B15: =SUMIF('Sales Data'!$C$3:$C$1044,A15,'Sales Data'!$H$3:$H$1044) -> 3555 | C15: =SUMIF('Sales Data'!$C$3:$C$1044,A15,'Sales Data'!$F$3:$F$1044) -> 56 | D15: =COUNTIF('Sales Data'!$C$3:$C$1044,A15) -> 40 | E15: =IFERROR(B15/B$21*100,0) -> 2.3238788
A16: Beverage | B16: =SUMIF('Sales Data'!$C$3:$C$1044,A16,'Sales Data'!$H$3:$H$1044) -> 3380 | C16: =SUMIF('Sales Data'!$C$3:$C$1044,A16,'Sales Data'!$F$3:$F$1044) -> 169 | D16: =COUNTIF('Sales Data'!$C$3:$C$1044,A16) -> 53 | E16: =IFERROR(B16/B$21*100,0) -> 2.2094825
A17: Combo | B17: =SUMIF('Sales Data'!$C$3:$C$1044,A17,'Sales Data'!$H$3:$H$1044) -> 2236 | C17: =SUMIF('Sales Data'!$C$3:$C$1044,A17,'Sales Data'!$F$3:$F$1044) -> 14 | D17: =COUNTIF('Sales Data'!$C$3:$C$1044,A17) -> 13 | E17: =IFERROR(B17/B$21*100,0) -> 1.4616576
A18: Bread | B18: =SUMIF('Sales Data'!$C$3:$C$1044,A18,'Sales Data'!$H$3:$H$1044) -> 797 | C18: =SUMIF('Sales Data'!$C$3:$C$1044,A18,'Sales Data'!$F$3:$F$1044) -> 13 | D18: =COUNTIF('Sales Data'!$C$3:$C$1044,A18) -> 10 | E18: =IFERROR(B18/B$21*100,0) -> 0.52099335
A19: Hot Dog | B19: =SUMIF('Sales Data'!$C$3:$C$1044,A19,'Sales Data'!$H$3:$H$1044) -> 700 | C19: =SUMIF('Sales Data'!$C$3:$C$1044,A19,'Sales Data'!$F$3:$F$1044) -> 10 | D19: =COUNTIF('Sales Data'!$C$3:$C$1044,A19) -> 6 | E19: =IFERROR(B19/B$21*100,0) -> 0.45758513
A20: Add-on | B20: =SUMIF('Sales Data'!$C$3:$C$1044,A20,'Sales Data'!$H$3:$H$1044) -> 540 | C20: =SUMIF('Sales Data'!$C$3:$C$1044,A20,'Sales Data'!$F$3:$F$1044) -> 14 | D20: =COUNTIF('Sales Data'!$C$3:$C$1044,A20) -> 9 | E20: =IFERROR(B20/B$21*100,0) -> 0.35299424
A21: TOTAL | B21: =SUM(B12:B20) -> 152977 | C21: =SUM(C12:C20) -> 1774 | D21: =SUM(D12:D20) -> 997 | E21: =SUM(E12:E20) -> 100
A24: TABLE 3: Item-wise Revenue, Pareto & ABC Classification
A25: Rank | B25: Item Name | C25: Category | D25: Revenue (₹) | E25: Qty Sold | F25: Avg Unit Price (₹) | G25: % of Total | H25: Cumulative % | I25: ABC Class | J25: Pareto Segment
A26: 1 | B26: Mix Veg Margharita Pizza | C26: Pizza | D26: =SUMIF('Sales Data'!$D$3:$D$1044,B26,'Sales Data'!$H$3:$H$1044) -> 18010 | E26: =SUMIF('Sales Data'!$D$3:$D$1044,B26,'Sales Data'!$F$3:$F$1044) -> 140 | F26: 129 | G26: =IFERROR(D26/$B$21*100,0) -> 11.773012 | H26: =SUM($G$26:G26) -> 11.773012 | I26: =IF(H26<=70,"A",IF(H26<=90,"B","C")) -> A | J26: Top 20%
A27: 2 | B27: Kulhad Pizza | C27: Pizza | D27: =SUMIF('Sales Data'!$D$3:$D$1044,B27,'Sales Data'!$H$3:$H$1044) -> 16335 | E27: =SUMIF('Sales Data'!$D$3:$D$1044,B27,'Sales Data'!$F$3:$F$1044) -> 165 | F27: =IFERROR(AVERAGEIF('Sales Data'!$D$3:$D$1044,B27,'Sales Data'!$G$3:$G$1044),0) -> 99 | G27: =IFERROR(D27/$B$21*100,0) -> 10.678076 | H27: =SUM($G$26:G27) -> 22.451087 | I27: =IF(H27<=70,"A",IF(H27<=90,"B","C")) -> A | J27: Top 20%
A28: 3 | B28: Cheese N Corn Pizza | C28: Pizza | D28: =SUMIF('Sales Data'!$D$3:$D$1044,B28,'Sales Data'!$H$3:$H$1044) -> 12570 | E28: =SUMIF('Sales Data'!$D$3:$D$1044,B28,'Sales Data'!$F$3:$F$1044) -> 130 | F28: 97 | G28: =IFERROR(D28/$B$21*100,0) -> 8.2169215 | H28: =SUM($G$26:G28) -> 30.668009 | I28: =IF(H28<=70,"A",IF(H28<=90,"B","C")) -> A | J28: Top 20%
A29: 4 | B29: Onion Cheese Pizza | C29: Pizza | D29: =SUMIF('Sales Data'!$D$3:$D$1044,B29,'Sales Data'!$H$3:$H$1044) -> 9314 | E29: =SUMIF('Sales Data'!$D$3:$D$1044,B29,'Sales Data'!$F$3:$F$1044) -> 126 | F29: =IFERROR(AVERAGEIF('Sales Data'!$D$3:$D$1044,B29,'Sales Data'!$G$3:$G$1044),0) -> 81.531646 | G29: =IFERROR(D29/$B$21*100,0) -> 6.088497 | H29: =SUM($G$26:G29) -> 36.756506 | I29: =IF(H29<=70,"A",IF(H29<=90,"B","C")) -> A | J29: Top 20%
A30: 5 | B30: Paneer Pizza | C30: Pizza | D30: =SUMIF('Sales Data'!$D$3:$D$1044,B30,'Sales Data'!$H$3:$H$1044) -> 8804 | E30: =SUMIF('Sales Data'!$D$3:$D$1044,B30,'Sales Data'!$F$3:$F$1044) -> 56 | F30: 157 | G30: =IFERROR(D30/$B$21*100,0) -> 5.7551135 | H30: =SUM($G$26:G30) -> 42.511619 | I30: =IF(H30<=70,"A",IF(H30<=90,"B","C")) -> A | J30: Top 20%
A31: 6 | B31: Tandoori Pizza | C31: Pizza | D31: =SUMIF('Sales Data'!$D$3:$D$1044,B31,'Sales Data'!$H$3:$H$1044) -> 8671 | E31: =SUMIF('Sales Data'!$D$3:$D$1044,B31,'Sales Data'!$F$3:$F$1044) -> 49 | F31: =IFERROR(AVERAGEIF('Sales Data'!$D$3:$D$1044,B31,'Sales Data'!$G$3:$G$1044),0) -> 177.33333 | G31: =IFERROR(D31/$B$21*100,0) -> 5.6681723 | H31: =SUM($G$26:G31) -> 48.179792 | I31: =IF(H31<=70,"A",IF(H31<=90,"B","C")) -> A | J31: Top 20%
A32: 7 | B32: Veg Burger | C32: Burger | D32: =SUMIF('Sales Data'!$D$3:$D$1044,B32,'Sales Data'!$H$3:$H$1044) -> 6786 | E32: =SUMIF('Sales Data'!$D$3:$D$1044,B32,'Sales Data'!$F$3:$F$1044) -> 174 | F32: =IFERROR(AVERAGEIF('Sales Data'!$D$3:$D$1044,B32,'Sales Data'!$G$3:$G$1044),0) -> 39 | G32: =IFERROR(D32/$B$21*100,0) -> 4.435961 | H32: =SUM($G$26:G32) -> 52.615753 | I32: =IF(H32<=70,"A",IF(H32<=90,"B","C")) -> A | J32: Top 20%
A33: 8 | B33: Spicy Mix Veg Pizza | C33: Pizza | D33: =SUMIF('Sales Data'!$D$3:$D$1044,B33,'Sales Data'!$H$3:$H$1044) -> 5550 | E33: =SUMIF('Sales Data'!$D$3:$D$1044,B33,'Sales Data'!$F$3:$F$1044) -> 30 | F33: 185 | G33: =IFERROR(D33/$B$21*100,0) -> 3.6279964 | H33: =SUM($G$26:G33) -> 56.243749 | I33: =IF(H33<=70,"A",IF(H33<=90,"B","C")) -> A | J33: Top 20%
A34: 9 | B34: Overloaded Cheese Pizza | C34: Pizza | D34: =SUMIF('Sales Data'!$D$3:$D$1044,B34,'Sales Data'!$H$3:$H$1044) -> 5487 | E34: =SUMIF('Sales Data'!$D$3:$D$1044,B34,'Sales Data'!$F$3:$F$1044) -> 25 | F34: =IFERROR(AVERAGEIF('Sales Data'!$D$3:$D$1044,B34,'Sales Data'!$G$3:$G$1044),0) -> 218.56522 | G34: =IFERROR(D34/$B$21*100,0) -> 3.5868137 | H34: =SUM($G$26:G34) -> 59.830563 | I34: =IF(H34<=70,"A",IF(H34<=90,"B","C")) -> A | J34: Top 20%
A35: 10 | B35: Veg Cheese Burger | C35: Burger | D35: =SUMIF('Sales Data'!$D$3:$D$1044,B35,'Sales Data'!$H$3:$H$1044) -> 4838 | E35: =SUMIF('Sales Data'!$D$3:$D$1044,B35,'Sales Data'!$F$3:$F$1044) -> 82 | F35: =IFERROR(AVERAGEIF('Sales Data'!$D$3:$D$1044,B35,'Sales Data'!$G$3:$G$1044),0) -> 59 | G35: =IFERROR(D35/$B$21*100,0) -> 3.1625669 | H35: =SUM($G$26:G35) -> 62.99313 | I35: =IF(H35<=70,"A",IF(H35<=90,"B","C")) -> A | J35: Bottom 80%
A36: 11 | B36: Baby Cheese Pizza | C36: Pizza | D36: =SUMIF('Sales Data'!$D$3:$D$1044,B36,'Sales Data'!$H$3:$H$1044) -> 4753 | E36: =SUMIF('Sales Data'!$D$3:$D$1044,B36,'Sales Data'!$F$3:$F$1044) -> 97 | F36: =IFERROR(AVERAGEIF('Sales Data'!$D$3:$D$1044,B36,'Sales Data'!$G$3:$G$1044),0) -> 49 | G36: =IFERROR(D36/$B$21*100,0) -> 3.107003 | H36: =SUM($G$26:G36) -> 66.100133 | I36: =IF(H36<=70,"A",IF(H36<=90,"B","C")) -> A | J36: Bottom 80%
A37: 12 | B37: Onion Capsicum Pizza | C37: Pizza | D37: =SUMIF('Sales Data'!$D$3:$D$1044,B37,'Sales Data'!$H$3:$H$1044) -> 4736 | E37: =SUMIF('Sales Data'!$D$3:$D$1044,B37,'Sales Data'!$F$3:$F$1044) -> 44 | F37: =IFERROR(AVERAGEIF('Sales Data'!$D$3:$D$1044,B37,'Sales Data'!$G$3:$G$1044),0) -> 120.85185 | G37: =IFERROR(D37/$B$21*100,0) -> 3.0958902 | H37: =SUM($G$26:G37) -> 69.196023 | I37: =IF(H37<=70,"A",IF(H37<=90,"B","C")) -> A | J37: Bottom 80%
A38: 13 | B38: Onion Paneer Pizza | C38: Pizza | D38: =SUMIF('Sales Data'!$D$3:$D$1044,B38,'Sales Data'!$H$3:$H$1044) -> 4556 | E38: =SUMIF('Sales Data'!$D$3:$D$1044,B38,'Sales Data'!$F$3:$F$1044) -> 24 | F38: =IFERROR(AVERAGEIF('Sales Data'!$D$3:$D$1044,B38,'Sales Data'!$G$3:$G$1044),0) -> 192.15789 | G38: =IFERROR(D38/$B$21*100,0) -> 2.9782255 | H38: =SUM($G$26:G38) -> 72.174248 | I38: =IF(H38<=70,"A",IF(H38<=90,"B","C")) -> B | J38: Bottom 80%
A39: 14 | B39: MrPizza Special Pizza | C39: Pizza | D39: =SUMIF('Sales Data'!$D$3:$D$1044,B39,'Sales Data'!$H$3:$H$1044) -> 4327 | E39: =SUMIF('Sales Data'!$D$3:$D$1044,B39,'Sales Data'!$F$3:$F$1044) -> 23 | F39: =IFERROR(AVERAGEIF('Sales Data'!$D$3:$D$1044,B39,'Sales Data'!$G$3:$G$1044),0) -> 189.90909 | G39: =IFERROR(D39/$B$21*100,0) -> 2.8285298 | H39: =SUM($G$26:G39) -> 75.002778 | I39: =IF(H39<=70,"A",IF(H39<=90,"B","C")) -> B | J39: Bottom 80%
A40: 15 | B40: Sweet Corn Paneer Pizza | C40: Pizza | D40: =SUMIF('Sales Data'!$D$3:$D$1044,B40,'Sales Data'!$H$3:$H$1044) -> 4267 | E40: =SUMIF('Sales Data'!$D$3:$D$1044,B40,'Sales Data'!$F$3:$F$1044) -> 23 | F40: =IFERROR(AVERAGEIF('Sales Data'!$D$3:$D$1044,B40,'Sales Data'!$G$3:$G$1044),0) -> 188.54545 | G40: =IFERROR(D40/$B$21*100,0) -> 2.7893082 | H40: =SUM($G$26:G40) -> 77.792086 | I40: =IF(H40<=70,"A",IF(H40<=90,"B","C")) -> B | J40: Bottom 80%
A41: 16 | B41: Capsicum Cheese Pizza | C41: Pizza | D41: =SUMIF('Sales Data'!$D$3:$D$1044,B41,'Sales Data'!$H$3:$H$1044) -> 3369 | E41: =SUMIF('Sales Data'!$D$3:$D$1044,B41,'Sales Data'!$F$3:$F$1044) -> 41 | F41: =IFERROR(AVERAGEIF('Sales Data'!$D$3:$D$1044,B41,'Sales Data'!$G$3:$G$1044),0) -> 87.787879 | G41: =IFERROR(D41/$B$21*100,0) -> 2.2022918 | H41: =SUM($G$26:G41) -> 79.994378 | I41: =IF(H41<=70,"A",IF(H41<=90,"B","C")) -> B | J41: Bottom 80%
A42: 17 | B42: Peppy Paneer Pizza | C42: Pizza | D42: =SUMIF('Sales Data'!$D$3:$D$1044,B42,'Sales Data'!$H$3:$H$1044) -> 3184 | E42: =SUMIF('Sales Data'!$D$3:$D$1044,B42,'Sales Data'!$F$3:$F$1044) -> 16 | F42: =IFERROR(AVERAGEIF('Sales Data'!$D$3:$D$1044,B42,'Sales Data'!$G$3:$G$1044),0) -> 199 | G42: =IFERROR(D42/$B$21*100,0) -> 2.0813586 | H42: =SUM($G$26:G42) -> 82.075737 | I42: =IF(H42<=70,"A",IF(H42<=90,"B","C")) -> B | J42: Bottom 80%
A43: 18 | B43: Cold Drink | C43: Beverage | D43: =SUMIF('Sales Data'!$D$3:$D$1044,B43,'Sales Data'!$H$3:$H$1044) -> 3140 | E43: =SUMIF('Sales Data'!$D$3:$D$1044,B43,'Sales Data'!$F$3:$F$1044) -> 157 | F43: =IFERROR(AVERAGEIF('Sales Data'!$D$3:$D$1044,B43,'Sales Data'!$G$3:$G$1044),0) -> 20 | G43: =IFERROR(D43/$B$21*100,0) -> 2.0525961 | H43: =SUM($G$26:G43) -> 84.128333 | I43: =IF(H43<=70,"A",IF(H43<=90,"B","C")) -> B | J43: Bottom 80%
...

Sheet Charts
A1: Mr. Pizza — Analysis Charts | T1: ABC Summary
A2: All charts generated from Summary Analysis sheet data. Data period: Sep 2023 – Jan 2024 | T2: Class | U2: Items | V2: Revenue (₹)
T3: A | U3: 12 | V3: 105854
T4: B | U4: 9 | V4: 31044
T5: C | U5: 26 | V5: 16079
T8: Top 10 by Qty
T9: Item | U9: Qty
T10: Veg Burger | U10: 174
T11: Kulhad Pizza | U11: 165
T12: Cold Drink | U12: 157
T13: Mix Veg Margharita | U13: 140
T14: Cheese N Corn Pizza | U14: 130
T15: Onion Cheese Pizza | U15: 126
T16: Baby Cheese Pizza | U16: 97
T17: Veg Cheese Burger | U17: 82
T18: Cold Coffee | U18: 59
T19: Paneer Pizza | U19: 56
